Workbook
Name categories: Setup!$A$11:$A$19
Name paymentModes: Setup!$D$11:$D$1000

Sheet Setup
A1: Year | B1: Salary | C1: Needs | D1: Wants | E1: Savings | G1: Enter current salary at B2. Assuming salary increases 10% per year. Update actuals every year This follows the 50:30:20 rule. Use the 'Daily Expense Tracker' sheet to add all expense details. Double click on a date row to select from calander. Update Category List and Payment Mode as needed. You will also have to assign colours to new items. This would be a one time setup. Go to Daily Expense Tracker > select the respective dropdown > edit > asssign colors > assign to all For any support please reach out to mayur.bhatolia@gmail.com @mayurbhatolia (instagram)
A2: 2026 | B2: 50000 | C2: =floor(B2*0.5,1) -> 25000 | D2: =floor(B2*0.3,1) -> 15000 | E2: =ceiling(B2*0.2,1) -> 10000
A3: 2027 | B3: =B2*1.1 -> 55000 | C3: =floor(B3*0.5,1) -> 27500 | D3: =floor(B3*0.3,1) -> 16500 | E3: =ceiling(B3*0.2,1) -> 11000
A4: 2028 | B4: =B3*1.1 -> 60500 | C4: =floor(B4*0.5,1) -> 30250 | D4: =floor(B4*0.3,1) -> 18150 | E4: =ceiling(B4*0.2,1) -> 12100
A5: 2029 | B5: =B4*1.1 -> 66550 | C5: =floor(B5*0.5,1) -> 33275 | D5: =floor(B5*0.3,1) -> 19965 | E5: =ceiling(B5*0.2,1) -> 13310
A6: 2030 | B6: =B5*1.1 -> 73205 | C6: =floor(B6*0.5,1) -> 36602 | D6: =floor(B6*0.3,1) -> 21961 | E6: =ceiling(B6*0.2,1) -> 14641
A10: Category List | B10: Type | D10: Payment Mode | K10: =IFERROR(__xludf.DUMMYFUNCTION("{""All""; FILTER(D11:D20, D11:D20<>"""")}"),"All") -> All
A11: Life Infrastructure | B11: Need | D11: Credit Card | K11: =IFERROR(__xludf.DUMMYFUNCTION("""COMPUTED_VALUE"""),"Credit Card") -> Credit Card
A12: Future Me | B12: Saving | D12: Debit Card | K12: =IFERROR(__xludf.DUMMYFUNCTION("""COMPUTED_VALUE"""),"Debit Card") -> Debit Card
A13: Performance & Growth | B13: Need | D13: UPI | K13: =IFERROR(__xludf.DUMMYFUNCTION("""COMPUTED_VALUE"""),"UPI") -> UPI
A14: Relationships & Generosity | B14: Want | D14: Cash | K14: =IFERROR(__xludf.DUMMYFUNCTION("""COMPUTED_VALUE"""),"Cash") -> Cash
A15: Lifestyle Enjoyment | B15: Want | D15: Bank Transfer | K15: =IFERROR(__xludf.DUMMYFUNCTION("""COMPUTED_VALUE"""),"Bank Transfer") -> Bank Transfer
A20: Weekly limit
A21: 10000

Sheet Daily Expense Tracker
A1: Date | B1: Description | C1: Category | D1: Amount | E1: Payment Mode | F1: Type | G1: Notes
A2: 46023 | B2: Uber late night - NYE | C2: Life Infrastructure | D2: 450 | E2: UPI | F2: Need | G2: NYE cab home
A3: 46023 | B3: Brunch out with friends | C3: Lifestyle Enjoyment | D3: 950 | E3: Credit Card | F3: Want | G3: New year brunch
A4: 46023 | B4: Swiggy dinner | C4: Lifestyle Enjoyment | D4: 380 | E4: UPI | F4: Want | G4: Too tired to cook
A5: 46024 | B5: House Rent | C5: Life Infrastructure | D5: 12000 | E5: Bank Transfer | F5: Need | G5: Monthly rent
A6: 46024 | B6: Groceries - BigBasket | C6: Life Infrastructure | D6: 1600 | E6: UPI | F6: Need | G6: Monthly stock
A7: 46024 | B7: Swiggy lunch | C7: Lifestyle Enjoyment | D7: 320 | E7: UPI | F7: Want | G7: Office lunch
A8: 46024 | B8: Chai tapri | C8: Lifestyle Enjoyment | D8: 30 | E8: Cash | F8: Want | G8: Evening chai
A9: 46025 | B9: Myntra sale - clothes | C9: Lifestyle Enjoyment | D9: 3200 | E9: Credit Card | F9: Want | G9: New year sale haul
A10: 46025 | B10: Movie + popcorn | C10: Lifestyle Enjoyment | D10: 800 | E10: UPI | F10: Want | G10: Weekend movie
A11: 46025 | B11: Dinner out - Barbeque Nation | C11: Lifestyle Enjoyment | D11: 1100 | E11: Credit Card | F11: Want | G11: Saturday dinner
A12: 46025 | B12: Uber rides | C12: Life Infrastructure | D12: 280 | E12: UPI | F12: Need | G12: Mall + movie
A13: 46026 | B13: Zomato brunch | C13: Lifestyle Enjoyment | D13: 550 | E13: UPI | F13: Want | G13: Lazy Sunday
... A290: 46124 | B290: Chai tapri | C290: Lifestyle Enjoyment | D290: 30 | E290: Cash | F290: Want | G290: Evening chai

Sheet Weekly Analysis
A1: Mode | B1: Quarter | D1: Week Start | E1: Week End | F1: Spend | G1: Limit | H1: Ratio
A2: Quarter | B2: Q1 | D2: 46385 | E2: 46026 | F2: 23880 | G2: 10000 | H2: 239
A3: Start Month | D3: 46027 | E3: 46033 | F3: 15957 | G3: 10000 | H3: 160
A4: End Month | D4: 46034 | E4: 46040 | F4: 12239 | G4: 10000 | H4: 122
A5: Category | B5: All | D5: 46041 | E5: 46047 | F5: 7010 | G5: 10000 | H5: 70
A6: Payment Mode | B6: All | D6: 46048 | E6: 46054 | F6: 17770 | G6: 10000 | H6: 178
D7: 46055 | E7: 46061 | F7: 15288 | G7: 10000 | H7: 153
D8: 46062 | E8: 46068 | F8: 13418 | G8: 10000 | H8: 134
D9: 46069 | E9: 46075 | F9: 6050 | G9: 10000 | H9: 61
D10: 46076 | E10: 46082 | F10: 18190 | G10: 10000 | H10: 182
D11: 46083 | E11: 46089 | F11: 16738 | G11: 10000 | H11: 167
D12: 46090 | E12: 46096 | F12: 14338 | G12: 10000 | H12: 143
D13: 46097 | E13: 46103 | F13: 12010 | G13: 10000 | H13: 120
D14: 46104 | E14: 46110 | F14: 9118 | G14: 10000 | H14: 91
D15: 46111 | E15: 46117 | F15: 26017 | G15: 10000 | H15: 260

Sheet Monthly Analysis
A1: Month | B1: Year | J1: Score
A2: Apr | B2: 2026 | J2: 10
A4: Date | B4: Spent
A5: {=DATE($B$2, MATCH($A$2, {"Jan","Feb","Mar","Apr","May","Jun","Jul","Aug","Sep","Oct","Nov","Dec"}, 0), 1) + SEQUENCE( DAY(EOMONTH( DATE($B$2, MATCH($A$2, {"Jan","Feb","Mar","Apr","May","Jun","Jul","Aug","Sep","Oct","Nov","Dec"}, 0), 1), 0 )), 1, 0, 1 )} -> 46113 | B5: =IFERROR(__xludf.DUMMYFUNCTION("MAP( A5:A1000, LAMBDA(d, IF(d="""","""", IFERROR( SUM( FILTER( 'Daily Expense Tracker'!D:D, 'Daily Expense Tracker'!A:A = d, ('Daily Expense Tracker'!F:F = ""Need"") + ('Daily"&" Expense Tracker'!F:F = ""Want"") ) ), 0 ) ) ) ) "),13850.0) -> 13850
A6: 46114 | B6: =IFERROR(__xludf.DUMMYFUNCTION("""COMPUTED_VALUE"""),1079.0) -> 1079
A7: 46115 | B7: =IFERROR(__xludf.DUMMYFUNCTION("""COMPUTED_VALUE"""),2180.0) -> 2180
A8: 46116 | B8: =IFERROR(__xludf.DUMMYFUNCTION("""COMPUTED_VALUE"""),1580.0) -> 1580
A9: 46117 | B9: =IFERROR(__xludf.DUMMYFUNCTION("""COMPUTED_VALUE"""),768.0) -> 768
A10: 46118 | B10: =IFERROR(__xludf.DUMMYFUNCTION("""COMPUTED_VALUE"""),1580.0) -> 1580
A11: 46119 | B11: =IFERROR(__xludf.DUMMYFUNCTION("""COMPUTED_VALUE"""),1260.0) -> 1260
A12: 46120 | B12: =IFERROR(__xludf.DUMMYFUNCTION("""COMPUTED_VALUE"""),1329.0) -> 1329
A13: 46121 | B13: =IFERROR(__xludf.DUMMYFUNCTION("""COMPUTED_VALUE"""),420.0) -> 420
A14: 46122 | B14: =IFERROR(__xludf.DUMMYFUNCTION("""COMPUTED_VALUE"""),1000.0) -> 1000
A15: 46123 | B15: =IFERROR(__xludf.DUMMYFUNCTION("""COMPUTED_VALUE"""),2330.0) -> 2330
A16: 46124 | B16: =IFERROR(__xludf.DUMMYFUNCTION("""COMPUTED_VALUE"""),930.0) -> 930
A17: 46125 | B17: =IFERROR(__xludf.DUMMYFUNCTION("""COMPUTED_VALUE"""),0.0) -> 0
A18: 46126 | B18: =IFERROR(__xludf.DUMMYFUNCTION("""COMPUTED_VALUE"""),0.0) -> 0
A19: 46127 | B19: =IFERROR(__xludf.DUMMYFUNCTION("""COMPUTED_VALUE"""),0.0) -> 0
A20: 46128 | B20: =IFERROR(__xludf.DUMMYFUNCTION("""COMPUTED_VALUE"""),0.0) -> 0
A21: 46129 | B21: =IFERROR(__xludf.DUMMYFUNCTION("""COMPUTED_VALUE"""),0.0) -> 0
A22: 46130 | B22: =IFERROR(__xludf.DUMMYFUNCTION("""COMPUTED_VALUE"""),0.0) -> 0
A23: 46131 | B23: =IFERROR(__xludf.DUMMYFUNCTION("""COMPUTED_VALUE"""),0.0) -> 0
A24: 46132 | B24: =IFERROR(__xludf.DUMMYFUNCTION("""COMPUTED_VALUE"""),0.0) -> 0
A25: 46133 | B25: =IFERROR(__xludf.DUMMYFUNCTION("""COMPUTED_VALUE"""),0.0) -> 0
A26: 46134 | B26: =IFERROR(__xludf.DUMMYFUNCTION("""COMPUTED_VALUE"""),0.0) -> 0
A27: 46135 | B27: =IFERROR(__xludf.DUMMYFUNCTION("""COMPUTED_VALUE"""),0.0) -> 0
A28: 46136 | B28: =IFERROR(__xludf.DUMMYFUNCTION("""COMPUTED_VALUE"""),0.0) -> 0
... A34: 46142 | B34: =IFERROR(__xludf.DUMMYFUNCTION("""COMPUTED_VALUE"""),0.0) -> 0
B35: =IFERROR(__xludf.DUMMYFUNCTION("""COMPUTED_VALUE"""),"")
B36: =IFERROR(__xludf.DUMMYFUNCTION("""COMPUTED_VALUE"""),"")
B37: =IFERROR(__xludf.DUMMYFUNCTION("""COMPUTED_VALUE"""),"")
B38: =IFERROR(__xludf.DUMMYFUNCTION("""COMPUTED_VALUE"""),"")
B39: =IFERROR(__xludf.DUMMYFUNCTION("""COMPUTED_VALUE"""),"")
B40: =IFERROR(__xludf.DUMMYFUNCTION("""COMPUTED_VALUE"""),"")
B41: =IFERROR(__xludf.DUMMYFUNCTION("""COMPUTED_VALUE"""),"")
B42: =IFERROR(__xludf.DUMMYFUNCTION("""COMPUTED_VALUE"""),"")
B43: =IFERROR(__xludf.DUMMYFUNCTION("""COMPUTED_VALUE"""),"")
B44: =IFERROR(__xludf.DUMMYFUNCTION("""COMPUTED_VALUE"""),"")
B45: =IFERROR(__xludf.DUMMYFUNCTION("""COMPUTED_VALUE"""),"")
B46: =IFERROR(__xludf.DUMMYFUNCTION("""COMPUTED_VALUE"""),"")
...

Sheet Yearly Calendar
A1: Year: 2026
A2: Last updated: 23:01
B3: Jan | H3: Feb | N3: Mar | U3: Apr | AA3: May | AG3: Jun | AM3: Jul | AS3: Aug | AZ3: Sep | BF3: Oct | BL3: Nov | BS3: Dec
A5: Mon
A6: Tue
A7: Wed
A8: Thu
A9: Fri
A10: Sat
A11: Sun

Sheet Calc
A1: Selected Date Range | G1: Category | H1: Budget | I1: Actual | J1: Difference
A2: {=DATE('Monthly Analysis'!B2, MATCH('Monthly Analysis'!A2, {"Jan","Feb","Mar","Apr","May","Jun","Jul","Aug","Sep","Oct","Nov","Dec"}, 0), 1)} -> 46113 | B2: =EDATE(A2, 1) -> 46143 | G2: Need | H2: {=INDEX(Setup!C:C, MATCH('Monthly Analysis'!$B$2, Setup!A:A, 0))} -> 25000 | I2: =SUMIF($C$5:C$15, G2, $B$5:$B$15) -> 22788 | J2: =H2-I2 -> 2212
G3: Want | H3: {=INDEX(Setup!D:D, MATCH('Monthly Analysis'!$B$2, Setup!A:A, 0))} -> 15000 | I3: =SUMIF($C$5:C$15, G3, $B$5:$B$15) -> 5518 | J3: =H3-I3 -> 9482
G4: Saving | H4: {=INDEX(Setup!E:E, MATCH('Monthly Analysis'!$B$2, Setup!A:A, 0))} -> 10000 | I4: =SUMIF($C$5:C$15, G4, $B$5:$B$15) -> 10000 | J4: =H4-I4 -> 0
A5: Category | B5: Actual Spend | C5: Type | D5: Total | E5: =SUM($B$6:$B$15) -> 38306
A6: =IFERROR(__xludf.DUMMYFUNCTION("FILTER(Setup!A11:A1000, Setup!A11:A1000<>"""")"),"Life Infrastructure") -> Life Infrastructure | B6: =SUMIFS( 'Daily Expense Tracker'!D:D, 'Daily Expense Tracker'!C:C, A6, 'Daily Expense Tracker'!A:A, ">=" & Calc!$A$2, 'Daily Expense Tracker'!A:A, "<" & Calc!$B$2 ) -> 21288 | C6: {=XLOOKUP(A6, Setup!A2:A12, Setup!B2:B12)} -> Need | D6: Amount Left | E6: {=INDEX(Setup!B:B, MATCH('Monthly Analysis'!B2, Setup!A:A, 0))-E5} -> 11694
A7: =IFERROR(__xludf.DUMMYFUNCTION("""COMPUTED_VALUE"""),"Future Me") -> Future Me | B7: =SUMIFS( 'Daily Expense Tracker'!D:D, 'Daily Expense Tracker'!C:C, A7, 'Daily Expense Tracker'!A:A, ">=" & Calc!$A$2, 'Daily Expense Tracker'!A:A, "<" & Calc!$B$2 ) -> 10000 | C7: {=XLOOKUP(A7, Setup!A3:A13, Setup!B3:B13)} -> Saving | D7: Percentage Left | E7: {=iferror(E6/INDEX(Setup!B:B, MATCH('Monthly Analysis'!B2, Setup!A:A, 0)),"NA")} -> 0.23388
A8: =IFERROR(__xludf.DUMMYFUNCTION("""COMPUTED_VALUE"""),"Performance & Growth") -> Performance & Growth | B8: =SUMIFS( 'Daily Expense Tracker'!D:D, 'Daily Expense Tracker'!C:C, A8, 'Daily Expense Tracker'!A:A, ">=" & Calc!$A$2, 'Daily Expense Tracker'!A:A, "<" & Calc!$B$2 ) -> 1500 | C8: {=XLOOKUP(A8, Setup!A4:A14, Setup!B4:B14)} -> Need
A9: =IFERROR(__xludf.DUMMYFUNCTION("""COMPUTED_VALUE"""),"Relationships & Generosity") -> Relationships & Generosity | B9: =SUMIFS( 'Daily Expense Tracker'!D:D, 'Daily Expense Tracker'!C:C, A9, 'Daily Expense Tracker'!A:A, ">=" & Calc!$A$2, 'Daily Expense Tracker'!A:A, "<" & Calc!$B$2 ) -> 500 | C9: {=XLOOKUP(A9, Setup!A5:A15, Setup!B5:B15)} -> Want
A10: =IFERROR(__xludf.DUMMYFUNCTION("""COMPUTED_VALUE"""),"Lifestyle Enjoyment") -> Lifestyle Enjoyment | B10: =SUMIFS( 'Daily Expense Tracker'!D:D, 'Daily Expense Tracker'!C:C, A10, 'Daily Expense Tracker'!A:A, ">=" & Calc!$A$2, 'Daily Expense Tracker'!A:A, "<" & Calc!$B$2 ) -> 5018 | C10: {=XLOOKUP(A10, Setup!A6:A16, Setup!B6:B16)} -> Want
A11: =IFERROR(__xludf.DUMMYFUNCTION("""COMPUTED_VALUE"""),"Weekly limit") -> Weekly limit
A12: =IFERROR(__xludf.DUMMYFUNCTION("""COMPUTED_VALUE"""),10000.0) -> 10000
